Workbook

Sheet Resumen
A1: Requisitos del proyecto integrador: salas de chat seguras
A2: Informe de requisitos funcionales, de seguridad y entregables
A4: Asignatura | B4: Software Seguro
A5: Docente | B5: Ing. Ángel Cudco
A6: Equipo | B6: Zaith Alejandro Manangón Vinueza, Stefany Maricela Díaz Antun, Andrés Isaias Cedeño Cuenca
A7: Fecha | B7: 13/10/2026
A9: 1. Objetivo
A10: Este informe reúne lo que debe cumplir la aplicación de salas de chat seguras: qué debe hacer (requisitos funcionales), qué debe proteger y cómo (requisitos de seguridad) y qué documentación y pruebas debe entregar el equipo. Cada requisito tiene un código, una descripción y un criterio de aceptación que permite comprobarlo.
A12: 2. Requisitos por tipo y prioridad
A13: Tipo | B13: Total | C13: Alta | D13: Media | E13: Baja
A14: Funcionales | B14: =COUNTA('Requisitos funcionales'!A2:A200) | C14: =COUNTIF('Requisitos funcionales'!F2:F200,"Alta") | D14: =COUNTIF('Requisitos funcionales'!F2:F200,"Media") | E14: =COUNTIF('Requisitos funcionales'!F2:F200,"Baja")
A15: De seguridad | B15: =COUNTA('Requisitos de seguridad'!A2:A200) | C15: =COUNTIF('Requisitos de seguridad'!F2:F200,"Alta") | D15: =COUNTIF('Requisitos de seguridad'!F2:F200,"Media") | E15: =COUNTIF('Requisitos de seguridad'!F2:F200,"Baja")
A16: Entregables | B16: =COUNTA('Entregables'!A2:A200) | C16: =COUNTIF('Entregables'!F2:F200,"Alta") | D16: =COUNTIF('Entregables'!F2:F200,"Media") | E16: =COUNTIF('Entregables'!F2:F200,"Baja")
A17: Total | B17: =SUM(B14:B16) | C17: =SUM(C14:C16) | D17: =SUM(D14:D16) | E17: =SUM(E14:E16)
A19: 3. Requisitos por categoría
A20: Categoría | B20: Requisitos | C20: Pestaña
A21: Cuenta del administrador | B21: =COUNTIF('Requisitos funcionales'!B2:B200,A21) | C21: Requisitos funcionales
A22: Gestión de salas | B22: =COUNTIF('Requisitos funcionales'!B2:B200,A22) | C22: Requisitos funcionales
A23: Supervisión | B23: =COUNTIF('Requisitos funcionales'!B2:B200,A23) | C23: Requisitos funcionales
A24: Acceso de participantes | B24: =COUNTIF('Requisitos funcionales'!B2:B200,A24) | C24: Requisitos funcionales
A25: Sesiones | B25: =COUNTIF('Requisitos funcionales'!B2:B200,A25) | C25: Requisitos funcionales
A26: Mensajería | B26: =COUNTIF('Requisitos funcionales'!B2:B200,A26) | C26: Requisitos funcionales
A27: Archivos multimedia | B27: =COUNTIF('Requisitos funcionales'!B2:B200,A27) | C27: Requisitos funcionales
A28: Auditoría | B28: =COUNTIF('Requisitos funcionales'!B2:B200,A28) | C28: Requisitos funcionales
A29: Autenticación y sesiones | B29: =COUNTIF('Requisitos de seguridad'!B2:B200,A29) | C29: Requisitos de seguridad
A30: Criptografía y claves | B30: =COUNTIF('Requisitos de seguridad'!B2:B200,A30) | C30: Requisitos de seguridad
A31: Contenido multimedia | B31: =COUNTIF('Requisitos de seguridad'!B2:B200,A31) | C31: Requisitos de seguridad
A32: Auditoría | B32: =COUNTIF('Requisitos de seguridad'!B2:B200,A32) | C32: Requisitos de seguridad
A33: Zero Trust y mínimo privilegio | B33: =COUNTIF('Requisitos de seguridad'!B2:B200,A33) | C33: Requisitos de seguridad
A34: Normas y enfoques | B34: =COUNTIF('Requisitos de seguridad'!B2:B200,A34) | C34: Requisitos de seguridad
A35: Análisis | B35: =COUNTIF('Entregables'!B2:B200,A35) | C35: Entregables
A36: Diseño | B36: =COUNTIF('Entregables'!B2:B200,A36) | C36: Entregables
A37: Implementación | B37: =COUNTIF('Entregables'!B2:B200,A37) | C37: Entregables
A38: Pruebas | B38: =COUNTIF('Entregables'!B2:B200,A38) | C38: Entregables
A39: Documentación | B39: =COUNTIF('Entregables'!B2:B200,A39) | C39: Entregables
A41: 4. Decisiones de interpretación
A42: Usuario: el enunciado no pide cuentas de usuario final. Un participante se identifica por su alias y su dispositivo dentro de la sala.
A43: Único dispositivo: una sesión activa por alias, ligada a la cookie de dispositivo. Un nuevo ingreso con el mismo alias se rechaza.
A44: Multimedia: por ahora imágenes PNG y JPEG. Otros formatos se agregan sin cambiar el proceso de análisis.
A45: Cierre de sala: expulsa a los participantes y no admite nuevos ingresos. El identificador de una sala cerrada no se reutiliza.
...

Sheet Requisitos funcionales
A1: Código | B1: Categoría | C1: Requisito | D1: Descripción | E1: Criterio de aceptación | F1: Prioridad
A2: RF-01 | B2: Cuenta del administrador | C2: Inicio de sesión del administrador | D2: El administrador ingresa con usuario y contraseña, y confirma con un código de verificación de un solo uso. | E2: Con credenciales válidas accede al panel. Con credenciales inválidas recibe un mensaje genérico y no entra. | F2: Alta
A3: RF-02 | B3: Cuenta del administrador | C3: Cierre de sesión del administrador | D3: El administrador cierra su sesión y esta queda invalidada. | E3: Después de cerrar sesión, las rutas del panel responden que no está autorizado. | F3: Media
A4: RF-03 | B4: Gestión de salas | C4: Crear una sala con identificador único | D4: El administrador crea una sala con un identificador único. El identificador se normaliza a minúsculas y sin espacios. | E4: No pueden existir dos salas con el mismo identificador. Un duplicado se rechaza con un error de conflicto. | F4: Alta
A5: RF-04 | B5: Gestión de salas | C5: Clave de acceso propia por sala | D5: Cada sala tiene una clave de acceso independiente, definida al crearla. | E5: Dos salas pueden tener claves distintas. Una clave débil (menos de 12 caracteres o de menos de 3 tipos de caracteres) se rechaza. | F5: Alta
A6: RF-05 | B6: Gestión de salas | C6: Número máximo de participantes | D6: Al crear la sala se define el máximo de participantes (de 2 a 50) y el administrador puede cambiarlo después. | E6: El cupo no puede quedar por debajo de los participantes conectados en ese momento. | F6: Alta
A7: RF-06 | B7: Gestión de salas | C7: Tipo de comunicación de la sala | D7: Cada sala se configura como solo texto, solo multimedia o texto y multimedia. | E7: El tipo se elige al crear la sala y se puede cambiar después. La sala hace cumplir su tipo. | F7: Alta
A8: RF-07 | B8: Gestión de salas | C8: Consultar salas | D8: El administrador ve la lista de salas con su tipo, su ocupación (conectados sobre cupo) y su estado. | E8: La lista muestra todas las salas con esos datos actualizados. | F8: Media
A9: RF-08 | B9: Gestión de salas | C9: Modificar una sala | D9: Desde el panel el administrador cambia la clave, el cupo y el tipo de una sala. | E9: Los cambios quedan guardados y se reflejan en la lista de salas. | F9: Media
A10: RF-09 | B10: Gestión de salas | C10: Cerrar una sala | D10: El administrador cierra una sala: se expulsa a sus participantes y deja de admitir ingresos. | E10: Los participantes conectados reciben el cierre. Un nuevo intento de ingreso a esa sala se rechaza. | F10: Alta
A11: RF-10 | B11: Supervisión | C11: Consultar los eventos de seguridad | D11: El administrador consulta los eventos de seguridad registrados y puede filtrarlos por severidad. | E11: La consulta devuelve los eventos ordenados del más reciente al más antiguo. | F11: Alta
A12: RF-11 | B12: Supervisión | C12: Alertas visibles en el panel | D12: El panel muestra una alerta cuando aparece un evento de severidad advertencia o crítica. | E12: En un máximo de 10 segundos aparecen la insignia con el contador y el aviso con la acción registrada. | F12: Media
... A31: RF-30 | B31: Auditoría | C31: Registro de eventos y actividades de seguridad | D31: El sistema registra los eventos relevantes: accesos, rechazos, cambios en las salas y archivos retenidos. | E31: Cada rechazo de seguridad genera un registro con fecha, actor y acción. | F31: Alta

Sheet Requisitos de seguridad
A1: Código | B1: Categoría | C1: Requisito | D1: Descripción | E1: Criterio de aceptación | F1: Prioridad
A2: RS-01 | B2: Autenticación y sesiones | C2: Autenticación segura del administrador | D2: La contraseña se guarda con Argon2id, el acceso exige un código TOTP, hay bloqueo tras 5 fallos con retraso progresivo y el token cambia al completar el segundo factor. | E2: Cinco intentos fallidos bloquean al usuario. Sin el código TOTP no hay acceso. Un código ya usado se rechaza. | F2: Alta
A3: RS-02 | B3: Autenticación y sesiones | C3: Autorización del administrador en cada operación | D3: Cada operación administrativa se valida en el servidor, en cada servicio, según el rol. | E3: Una petición a una ruta de administración sin identidad de administrador responde que no está autorizada. | F3: Alta
A4: RS-03 | B4: Autenticación y sesiones | C4: Clave de sala protegida | D4: La clave de sala se guarda solo como hash Argon2id con sal. Nunca existe en claro. | E4: Ninguna columna de la base de datos contiene la clave y el hash empieza con $argon2id$. | F4: Alta
A5: RS-04 | B5: Autenticación y sesiones | C5: Ingreso controlado por intentos | D5: El ingreso exige identificador y clave, y limita los intentos fallidos por IP, por dispositivo y por sala. | E5: Superado el límite, el ingreso responde que hay demasiados intentos. | F5: Alta
A6: RS-05 | B6: Autenticación y sesiones | C6: Sesión ligada al dispositivo | D6: La sesión del participante queda atada a su dispositivo y se comprueba en cada petición. | E6: Una sesión copiada a otro dispositivo es rechazada. | F6: Alta
A7: RS-06 | B7: Autenticación y sesiones | C7: Control de sesiones activas | D7: Alias único activo, cupo atómico, una sola conexión por sesión, expiración y barrido de sesiones caídas. | E7: Con 20 ingresos simultáneos y cupo 5 se aceptan exactamente 5. Una segunda conexión de la misma sesión reemplaza a la anterior. | F7: Alta
A8: RS-07 | B8: Autenticación y sesiones | C8: Cierre seguro de conexiones | D8: Al terminar una sesión el token queda inválido, se libera el cupo, se avisa a la sala y se registra el evento. | E8: Después de salir, el token ya no sirve y el alias queda libre. | F8: Alta
A9: RS-08 | B9: Autenticación y sesiones | C9: Rechazo de credenciales mal usadas | D9: Un token de sala usado en otro equipo, o en rutas de administración, se rechaza. | E9: Una cookie de sala enviada a una ruta de administración responde que no está autorizada. | F9: Alta
A10: RS-09 | B10: Criptografía y claves | C10: Confidencialidad en tránsito | D10: Todo mensaje viaja cifrado: TLS 1.3 hasta el servidor y AES-256-GCM por conexión sobre un acuerdo ECDH efímero. | E10: Las tramas capturadas no contienen texto legible. Los vectores de prueba coinciden entre Python y el navegador. | F10: Alta
A11: RS-10 | B11: Criptografía y claves | C11: Integridad de los mensajes | D11: Cada trama se autentica (AES-GCM con sala, sesión, dirección y número de secuencia como datos asociados) y se rechaza la repetición. | E11: Una trama alterada cierra la conexión y genera una alerta crítica. Una trama repetida se rechaza. | F11: Alta
A12: RS-11 | B12: Criptografía y claves | C12: Autenticidad de las comunicaciones | D12: El servidor se autentica con un saludo firmado (ECDSA), el remitente se toma de la sesión verificada y se valida el origen de la conexión. | E12: Un participante no puede suplantar a otro. Una conexión desde un origen no permitido se cierra. | F12: Alta
... A35: RS-34 | B35: Normas y enfoques | C35: ISO/IEC 27034 | D35: Existe un marco normativo de la aplicación y cada control de seguridad tiene su medida de verificación. | E35: Cada control de seguridad de la aplicación tiene una prueba o evidencia asociada. | F35: Media

Sheet Entregables
A1: Código | B1: Categoría | C1: Requisito | D1: Descripción | E1: Criterio de aceptación | F1: Prioridad
A2: RP-01 | B2: Análisis | C2: Análisis de activos, amenazas, vulnerabilidades y riesgos | D2: Identificación de activos, amenazas y vulnerabilidades, con su valoración y su tratamiento. | E2: Las Tablas 1 a 4 de la Tarea 2 están completas e incluyen el riesgo R16 propuesto. | F2: Alta
A3: RP-02 | B3: Análisis | C3: Requisitos funcionales y de seguridad | D3: Lista de requisitos con identificador, descripción y criterio de aceptación. | E3: Este documento. | F3: Alta
A4: RP-03 | B4: Diseño | C4: Arquitectura de la solución | D4: Diseño de la arquitectura de microservicios, del modelo de confianza y del protocolo criptográfico. | E4: La especificación de diseño está aprobada por el equipo. | F4: Alta
A5: RP-04 | B5: Implementación | C5: Aplicación funcional | D5: Aplicación de salas de chat seguras con panel de administración. | E5: La aplicación corre con un solo comando en local y en un servidor con certificado válido. | F5: Alta
A6: RP-05 | B6: Pruebas | C6: Pruebas de eficacia de los controles | D6: Pruebas automatizadas por riesgo, pruebas de punta a punta y calibración del estegoanálisis. | E6: El informe de pruebas muestra los resultados por servicio y por requisito. | F6: Alta
A7: RP-06 | B7: Documentación | C7: Justificación criptográfica | D7: Justificación de los algoritmos, los protocolos y la gestión de claves. | E7: El documento está entregado y cubre algoritmos, protocolo y ciclo de vida de las claves. | F7: Alta
A8: RP-07 | B8: Documentación | C8: Relación de los controles ISO con riesgos y mecanismos | D8: Matriz de los controles de ISO/IEC 27001 y 27034 con los riesgos y los mecanismos implementados. | E8: El documento de cumplimiento y la trazabilidad de riesgos están completos. | F8: Alta
A9: RP-08 | B9: Documentación | C9: Evidencia de Zero Trust, Secure by Design y Shift Left | D9: Documentación técnica que explica cómo se aplica cada enfoque. | E9: El documento de cumplimiento incluye la evidencia por cada principio. | F9: Alta
A10: RP-09 | B10: Pruebas | C10: Demostración funcional | D10: Demostración de las comunicaciones protegidas, el control de acceso, la gestión de sesiones y la detección de multimedia manipulada. | E10: El guion se ejecuta de punta a punta con la aplicación en funcionamiento. | F10: Media
